<?xml version="1.0" encoding="utf-8"?>
<robot name="amr" xmlns:xacro="http://ros.org/wiki/xacro">

<xacro:include filename="$(find amr_description)/urdf/amr_gazebo.xacro" />
<xacro:include filename="$(find amr_description)/urdf/amr_ros2_control.xacro" />


  <link name="base_footprint"/>

  <link
    name="base_link">
    <visual>
      <origin
        xyz="0 0 0"
        rpy="0 0 0" />
      <geometry>
        <mesh
          filename="package://amr_description/meshes/base_link.stl" scale="0.001 0.001 0.001"/>
      </geometry>
      <material
        name="">
        <color
          rgba="0.792156862745098 0.819607843137255 0.933333333333333 1" />
      </material>
    </visual>

    <!--collision>
      <origin
        xyz="0 0 0"
        rpy="0 0 0" />
      <geometry>
        <mesh
          filename="package://amr_description/meshes/base_link.stl" scale="0.001 0.001 0.001" />
      </geometry>
    </collision-->

    <inertial>
      <origin
        xyz="0 6.198e-8 1.241e-2"
        rpy="0 0 0" />
      <mass
        value="1.501384" />
      <inertia
        ixx="8.726e-3"
        ixy="-6.235e-9"
        ixz="3.0913613e-5"
        iyy="1.528e-2"
        iyz="-0.537e-9"
        izz="2.338e-2" />
    </inertial>

  </link>

  <joint name="base_footprint_to_base_link" type="fixed">
    <parent link="base_footprint"/>
    <child link="base_link"/>
    <origin xyz="0 0 0.09" rpy="0 0 0"/>
  </joint>

  <link
    name="front_link_right_side">
    <visual>
      <origin
        xyz="0 0 0"
        rpy="1.57 0 0" />
      <geometry>
        <mesh
          filename="package://amr_description/meshes/front_link_right_side.stl" scale="0.001 0.001 0.001"/>
      </geometry>
      <material
        name="">
        <color
          rgba="0.792156862745098 0.819607843137255 0.933333333333333 1" />
      </material>
    </visual>

    <collision>
      <origin
        xyz="0 0 0"
        rpy="1.57 0 0" />
      <geometry>
        <mesh
          filename="package://amr_description/meshes/front_link_right_side.stl" scale="0.001 0.001 0.001" />
      </geometry>
    </collision>

    <inertial>
      <origin
        xyz="3.742e-3 -3.947e-3 -13.785e-3"
        rpy="0 0 0" />
      <mass
        value="42.207e-3" />
      <inertia
        ixx="6.947405e-6"
        ixy="-0.158e-9"
        ixz="1.913789e-6"
        iyy="7.4644517e-5"
        iyz="0.883e-9"
        izz="6.7918278e-5" />
    </inertial>

  </link>

  <joint name="front_right_link_revolute" type="revolute">
    <parent link="base_link"/>
    <child link="front_link_right_side"/>
    <origin xyz="0.068501 -0.11 0.01414" rpy="0 0 0"/>
    <axis xyz="0 1 0"/>
    <limit
      lower="-1.13446"
      upper="0.750492"
      effort="10000000"
      velocity="10000000" />
    <dynamics
      damping="0.1"
      friction="0.2" />
  </joint>

  <link
    name="front_link_left_side">
    <visual>
      <origin
        xyz="0 0 0"
        rpy="0 0 0" />
      <geometry>
        <mesh
          filename="package://amr_description/meshes/front_link_left_side.stl" scale="0.001 0.001 0.001"/>
      </geometry>
      <material
        name="">
        <color
          rgba="0.792156862745098 0.819607843137255 0.933333333333333 1" />
      </material>
    </visual>

    <collision>
      <origin
        xyz="0 0 0"
        rpy="0 0 0" />
      <geometry>
        <mesh
          filename="package://amr_description/meshes/front_link_left_side.stl" scale="0.001 0.001 0.001" />
      </geometry>
    </collision>

    <inertial>
      <origin
        xyz="3.742e-3 3.947e-3 -13.785e-3"
        rpy="0 0 0" />
      <mass
        value="42.207e-3" />
      <inertia
        ixx="6.947405e-6"
        ixy="-0.158e-9"
        ixz="1.913789e-6"
        iyy="7.4644517e-5"
        iyz="0.883e-9"
        izz="6.7918278e-5" />
    </inertial>
  </link>

  <joint name="front_left_link_revolute" type="revolute">
    <parent link="base_link"/>
    <child link="front_link_left_side"/>
    <origin xyz="0.068501 0.11 0.01414" rpy="0 0 0"/>
    <axis xyz="0 1 0"/>
    <limit
      lower="-1.13446"
      upper="0.750492"
      effort="10000000"
      velocity="10000000" />
    <dynamics
      damping="0.1"
      friction="0.2" />
  </joint>

  <link
    name="back_link_left_side">
    <visual>
      <origin
        xyz="0 0 0"
        rpy="0 0 0" />
      <geometry>
        <mesh
          filename="package://amr_description/meshes/back_link_left_side.stl" scale="0.001 0.001 0.001"/>
      </geometry>
      <material
        name="">
        <color
          rgba="0.792156862745098 0.819607843137255 0.933333333333333 1" />
      </material>
    </visual>

    <collision>
      <origin
        xyz="0 0 0"
        rpy="0 0 0" />
      <geometry>
        <mesh
          filename="package://amr_description/meshes/back_link_left_side.stl" scale="0.001 0.001 0.001" />
      </geometry>
    </collision>

    <inertial>
      <origin
        xyz="2.151e-10 3.981e-3 -11.017e-3"
        rpy="0 0 0" />
      <mass
        value="12.076e-3" />
      <inertia
        ixx="2.205e-6"
        ixy="-4.149e-18"
        ixz="3.479e-14"
        iyy="2.451457e-6"
        iyz="0.434e-9"
        izz="3.35403e-7" />
    </inertial>
  </link>

  <joint name="back_left_link_revolute" type="fixed">
    <parent link="base_link"/>
    <child link="back_link_left_side"/>
    <origin xyz="-0.131499 0.11 0.01414" rpy="0 0 0"/>
  </joint>

  <link
    name="back_link_right_side">
    <visual>
      <origin
        xyz="0 0 0"
        rpy="0 0 0" />
      <geometry>
        <mesh
          filename="package://amr_description/meshes/back_link_right_side.stl" scale="0.001 0.001 0.001"/>
      </geometry>
      <material
        name="">
        <color
          rgba="0.792156862745098 0.819607843137255 0.933333333333333 1" />
      </material>
    </visual>

    <collision>
      <origin
        xyz="0 0 0"
        rpy="0 0 0" />
      <geometry>
        <mesh
          filename="package://amr_description/meshes/back_link_right_side.stl" scale="0.001 0.001 0.001" />
      </geometry>
    </collision>

    <inertial>
      <origin
        xyz="-2.151e-10 -3.981e-3 -11.017e-3"
        rpy="0 0 0" />
      <mass
        value="12.076e-3" />
      <inertia
        ixx="2.205e-6"
        ixy="-4.149e-18"
        ixz="-3.479e-14"
        iyy="2.451457e-6"
        iyz="-0.434e-9"
        izz="3.35403e-7" />
    </inertial>

  </link>

  <joint name="back_right_link_revolute" type="fixed">
    <parent link="base_link"/>
    <child link="back_link_right_side"/>
    <origin xyz="-0.131499 -0.11 0.01414" rpy="0 0 0"/>
  </joint>

  <link
    name="back_wheel_right_side">
    <visual>
      <origin
        xyz="0 0 0"
        rpy="1.57 0 0" />
      <geometry>
        <mesh
          filename="package://amr_description/meshes/back_wheel_right_side.stl" scale="0.001 0.001 0.001"/>
      </geometry>
      <material
        name="">
        <color
          rgba="0.792156862745098 0.819607843137255 0.933333333333333 1" />
      </material>
    </visual>

    <collision>
      <origin
        xyz="0 0 0"
        rpy="1.57 0 0" />
      <geometry>
        <mesh
          filename="package://amr_description/meshes/back_wheel_right_side.stl" scale="0.001 0.001 0.001" />
      </geometry>
      <surface>
        <friction>
          <ode>
            <mu>10.0</mu> <!-- High friction -->
            <mu2>10.0</mu2>
          </ode>
        </friction>
      </surface>
    </collision>

    <inertial>
      <origin
        xyz="-0.29e-3 -3.1731e-2 0.025e-3"
        rpy="0 0 0" />
      <mass
        value="0.595006" />
      <inertia
        ixx="3.284e-4"
        ixy="-0.003e-9"
        ixz="-45.417e-9"
        iyy="3.679e-4"
        iyz="-6.851e-9"
        izz="3.288e-4" />
    </inertial>
  </link>

  <joint name="back_right_wheel_revolute" type="continuous">
    <parent link="back_link_right_side"/>
    <child link="back_wheel_right_side"/>
    <origin xyz="0 -0.0065 -0.03514" rpy="0 0 0"/>
    <axis xyz="0 1 0"/>
    <limit
      effort="10000000"
      velocity="10000000" />
    <dynamics
      damping="0.1"
      friction="0.2" />
  </joint>

  <link
    name="back_wheel_left_side">
    <visual>
      <origin
        xyz="0 0 0"
        rpy="1.57 0 0" />
      <geometry>
        <mesh
          filename="package://amr_description/meshes/back_wheel_left_side.stl" scale="0.001 0.001 0.001"/>
      </geometry>
      <material
        name="">
        <color
          rgba="0.792156862745098 0.819607843137255 0.933333333333333 1" />
      </material>
    </visual>

    <collision>
      <origin
        xyz="0 0 0"
        rpy="1.57 0 0" />
      <geometry>
        <mesh
          filename="package://amr_description/meshes/back_wheel_left_side.stl" scale="0.001 0.001 0.001" />
      </geometry>
      <surface>
        <friction>
          <ode>
            <mu>10.0</mu> <!-- High friction -->
            <mu2>10.0</mu2>
          </ode>
        </friction>
      </surface>
    </collision>

    <inertial>
      <origin
        xyz="-0.29e-3 3.1731e-2 0.025e-3"
        rpy="0 0 0" />
      <mass
        value="0.595006" />
      <inertia
        ixx="3.284e-4"
        ixy="-0.003e-9"
        ixz="-45.417e-9"
        iyy="3.679e-4"
        iyz="-6.851e-9"
        izz="3.288e-4" />
    </inertial>
  </link>

  <joint name="back_left_wheel_revolute" type="continuous">
    <parent link="back_link_left_side"/>
    <child link="back_wheel_left_side"/>
    <origin xyz="0 0.0065 -0.03514" rpy="0 0 0"/>
    <axis xyz="0 1 0"/>
    <limit
      effort="10000000"
      velocity="10000000" />
    <dynamics
      damping="0.1"
      friction="0.2" />
  </joint>

  <link
    name="middle_wheel_left_side">
    <visual>
      <origin
        xyz="0 0 0"
        rpy="1.57 0 0" />
      <geometry>
        <mesh
          filename="package://amr_description/meshes/middle_wheel_left_side.stl" scale="0.001 0.001 0.001"/>
      </geometry>
      <material
        name="">
        <color
          rgba="0.792156862745098 0.819607843137255 0.933333333333333 1" />
      </material>
    </visual>

    <collision>
      <origin
        xyz="0 0 0"
        rpy="1.57 0 0" />
      <geometry>
        <mesh
          filename="package://amr_description/meshes/middle_wheel_left_side.stl" scale="0.001 0.001 0.001" />
      </geometry>
      <surface>
        <friction>
          <ode>
            <mu>10.0</mu> <!-- High friction -->
            <mu2>10.0</mu2>
          </ode>
        </friction>
      </surface>
    </collision>

    <inertial>
      <origin
        xyz="-0.29e-3 3.1731e-2 0.025e-3"
        rpy="0 0 0" />
      <mass
        value="0.595006" />
      <inertia
        ixx="3.284e-4"
        ixy="-0.003e-9"
        ixz="-45.417e-9"
        iyy="3.679e-4"
        iyz="-6.851e-9"
        izz="3.288e-4" />
    </inertial>
  </link>

  <joint name="middle_left_wheel_revolute" type="continuous">
    <parent link="front_link_left_side"/>
    <child link="middle_wheel_left_side"/>
    <origin xyz="-0.072288 0.0065 -0.034343" rpy="0 0 0"/>
    <axis xyz="0 1 0"/>
    <limit
      effort="10000000"
      velocity="10000000" />
    <dynamics
      damping="0.1"
      friction="0.2" />
  </joint>

  <link
    name="middle_wheel_right_side">
    <visual>
      <origin
        xyz="0 0 0"
        rpy="1.57 0 0" />
      <geometry>
        <mesh
          filename="package://amr_description/meshes/middle_wheel_right_side.stl" scale="0.001 0.001 0.001"/>
      </geometry>
      <material
        name="">
        <color
          rgba="0.792156862745098 0.819607843137255 0.933333333333333 1" />
      </material>
    </visual>

    <collision>
      <origin
        xyz="0 0 0"
        rpy="1.57 0 0" />
      <geometry>
        <mesh
          filename="package://amr_description/meshes/middle_wheel_right_side.stl" scale="0.001 0.001 0.001" />
      </geometry>
      <surface>
        <friction>
          <ode>
            <mu>10.0</mu> <!-- High friction -->
            <mu2>10.0</mu2>
          </ode>
        </friction>
      </surface>
    </collision>

    <inertial>
      <origin
        xyz="-0.29e-3 -3.1731e-2 0.025e-3"
        rpy="0 0 0" />
      <mass
        value="0.595006" />
      <inertia
        ixx="3.284e-4"
        ixy="-0.003e-9"
        ixz="-45.417e-9"
        iyy="3.679e-4"
        iyz="-6.851e-9"
        izz="3.288e-4" />
    </inertial>

  </link>

  <joint name="middle_right_wheel_revolute" type="continuous">
    <parent link="front_link_right_side"/>
    <child link="middle_wheel_right_side"/>
    <origin xyz="-0.072288 -0.0065 -0.034343" rpy="0 0 0"/>
    <axis xyz="0 1 0"/>
    <limit
      effort="10000000"
      velocity="10000000" />
    <dynamics
      damping="0.1"
      friction="0.2" />
  </joint>

  <link
    name="front_wheel_left_side">
    <visual>
      <origin
        xyz="0 0 0"
        rpy="1.57 0 0" />
      <geometry>
        <mesh
          filename="package://amr_description/meshes/front_wheel_left_side.stl" scale="0.001 0.001 0.001"/>
      </geometry>
      <material
        name="">
        <color
          rgba="0.792156862745098 0.819607843137255 0.933333333333333 1" />
      </material>
    </visual>

    <collision>
      <origin
        xyz="0 0 0"
        rpy="1.57 0 0" />
      <geometry>
        <mesh
          filename="package://amr_description/meshes/front_wheel_left_side.stl" scale="0.001 0.001 0.001" />
      </geometry>
      <surface>
        <friction>
          <ode>
            <mu>10.0</mu> <!-- High friction -->
            <mu2>10.0</mu2>
          </ode>
        </friction>
      </surface>
    </collision>

    <inertial>
      <origin
        xyz="0.004e-3 37.498e-3 -0.025e-3"
        rpy="0 0 0" />
      <mass
        value="1.030" />
      <inertia
        ixx="7.791e-4"
        ixy="-0.013e-9"
        ixz="-1.04741e-7"
        iyy="8.515e-4"
        iyz="2.7531e-8"
        izz="7.801e-4" />
    </inertial>


  </link>

  <joint name="front_left_wheel_revolute" type="continuous">
    <parent link="front_link_left_side"/>
    <child link="front_wheel_left_side"/>
    <origin xyz="0.082708 0.0065 -0.035489" rpy="0 0 0"/>
    <axis xyz="0 1 0"/>
    <limit
      effort="10000000"
      velocity="10000000" />
    <dynamics
      damping="0.1"
      friction="0.2" />
  </joint>

  <link
    name="front_wheel_right_side">
    <visual>
      <origin
        xyz="0 0 0"
        rpy="1.57 0 0" />
      <geometry>
        <mesh
          filename="package://amr_description/meshes/front_wheel_right_side.stl" scale="0.001 0.001 0.001"/>
      </geometry>
      <material
        name="">
        <color
          rgba="0.792156862745098 0.819607843137255 0.933333333333333 1" />
      </material>
    </visual>

    <collision>
      <origin
        xyz="0 0 0"
        rpy="1.57 0 0" />
      <geometry>
        <mesh
          filename="package://amr_description/meshes/front_wheel_right_side.stl" scale="0.001 0.001 0.001" />
      </geometry>
      <surface>
        <friction>
          <ode>
            <mu>10.0</mu> <!-- High friction -->
            <mu2>10.0</mu2>
          </ode>
        </friction>
      </surface>
    </collision>

    <inertial>
      <origin
        xyz="0.004e-3 -37.498e-3 -0.025e-3"
        rpy="0 0 0" />
      <mass
        value="1.030" />
      <inertia
        ixx="7.791e-4"
        ixy="-0.013e-9"
        ixz="-1.04741e-7"
        iyy="8.515e-4"
        iyz="2.7531e-8"
        izz="7.801e-4" />
    </inertial>

  </link>

  <joint name="front_right_wheel_revolute" type="continuous">
    <parent link="front_link_right_side"/>
    <child link="front_wheel_right_side"/>
    <origin xyz="0.082708 -0.0065 -0.035489" rpy="0 0 0"/>
    <axis xyz="0 1 0"/>
    <limit
      effort="10000000"
      velocity="10000000" />
    <dynamics
      damping="0.1"
      friction="0.2" />
  </joint>

  <link name="imu_link">
    <visual>
      <geometry>
        <box size="0.02 0.02 0.005"/>
      </geometry>
      <material name="black">
				<color rgba="0 0 0 1"/>
			</material>
    </visual>
  </link>

  <joint name="imu_base_joint" type="fixed">
      <parent link="base_link"/>
      <child link="imu_link"/>
      <origin xyz="0 0 0.005" rpy="0 0 0"/>
      <axis xyz="0 0 0"/>
  </joint>

<link
    name="connector">
    <visual>
      <origin
        xyz="0 0 0"
        rpy="0 0 0" />
      <geometry>
        <mesh
          filename="package://amr_description/meshes/connector.stl" scale="0.001 0.001 0.001"/>
      </geometry>
      <material
        name="">
        <color
          rgba="0.792156862745098 0.819607843137255 0.933333333333333 1" />
      </material>
    </visual>
    <collision>
      <origin
        xyz="0 0 0"
        rpy="0 0 0" />
      <geometry>
        <mesh
          filename="package://amr_description/meshes/connector.stl" scale="0.001 0.001 0.001" />
      </geometry>
    </collision>
    <inertial>
      <origin
        xyz="0 0 0.025"
        rpy="0 0 0" />
      <mass
        value="12.076e-3" />
      <inertia
        ixx="2.205e-6"
        ixy="-4.149e-18"
        ixz="-3.479e-14"
        iyy="2.451457e-6"
        iyz="-0.434e-9"
        izz="3.35403e-7" />
    </inertial>
  </link>

  



  <joint name="connector_base_joint" type="fixed">
      <parent link="base_link"/>
      <child link="connector"/>
      <origin xyz="0.0685 0 0.022079" rpy="0 0 0"/>
      <axis xyz="0 0 0"/>
  </joint>

  <link
    name="prism_bottom_tab">
    <visual>
      <origin
        xyz="0 0 0"
        rpy="0 0 0" />
      <geometry>
        <mesh
          filename="package://amr_description/meshes/prism_bottom_tab.stl" scale="0.001 0.001 0.001"/>
      </geometry>
      <material
        name="">
        <color
          rgba="0.792156862745098 0.819607843137255 0.933333333333333 1" />
      </material>
    </visual>
  </link>

  <joint name="prism_bottom_tab_base_joint" type="fixed">
      <parent link="base_link"/>
      <child link="prism_bottom_tab"/>
      <origin xyz="-0.045604 0 0.005" rpy="0 0 0"/>
      <axis xyz="0 0 0"/>
  </joint>

  <link
    name="prismatic_joint_bottom_hc">
    <visual>
      <origin
        xyz="0 0 0"
        rpy="0 0 0" />
      <geometry>
        <mesh
          filename="package://amr_description/meshes/prismatic_joint_bottom_hc.stl" scale="0.001 0.001 0.001"/>
      </geometry>
      <material
        name="">
        <color
          rgba="0.792156862745098 0.819607843137255 0.933333333333333 1" />
      </material>
    </visual>
  </link>

  <joint name="hc_bt_joint" type="fixed">
      <parent link="prism_bottom_tab"/>
      <child link="prismatic_joint_bottom_hc"/>
      <origin xyz="0 0 0.012809" rpy="0 0 0"/>
      <!--axis xyz="0 1 0"/>
    <limit
      effort="10000000"
      velocity="10000000" />
    <dynamics
      damping="0.1"
      friction="0.2" /-->
  </joint>

  <link
    name="prismatic_joint_top_sc">
    <visual>
      <origin
        xyz="0 0 0"
        rpy="0 0.7382 0" />
      <geometry>
        <mesh
          filename="package://amr_description/meshes/prismatic_joint_top_sc.stl" scale="0.001 0.001 0.001"/>
      </geometry>
      <material
        name="">
        <color
          rgba="0.792156862745098 0.819607843137255 0.933333333333333 1" />
      </material>
    </visual>
  </link>

  <joint name="sc_hc_joint" type="fixed">
      <parent link="prismatic_joint_bottom_hc"/>
      <child link="prismatic_joint_top_sc"/>
      <origin xyz="0.011825 0 0.005501" rpy="0 -0.7382 0"/>
      <!--limit effort="1000.0" lower="0.0" upper="0.05" velocity="0.5"/-->
    
  </joint>

  <link
    name="prism_top_tab">
    <visual>
      <origin
        xyz="0 0 0"
        rpy="0 0 0" />
      <geometry>
        <mesh
          filename="package://amr_description/meshes/prism_top_tab.stl" scale="0.001 0.001 0.001"/>
      </geometry>
      <material
        name="">
        <color
          rgba="0.792156862745098 0.819607843137255 0.933333333333333 1" />
      </material>
    </visual>
  </link>

  <joint name="top_tab_sc_joint" type="fixed">
      <parent link="prismatic_joint_top_sc"/>
      <child link="prism_top_tab"/>
      <origin xyz="0.068867 0 -0.004082" rpy="0 0.7382 0"/>
      <!--axis xyz="0 1 0"/>
      <limit
        effort="10000000"
        velocity="10000000" />
      <dynamics
        damping="0.1"
        friction="0.2" /-->
  </joint>

  <link
    name="delivery_box">
    <visual>
      <origin
        xyz="0 0 0"
        rpy="0 0 0" />
      <geometry>
        <mesh
          filename="package://amr_description/meshes/delivery_box.stl" scale="0.001 0.001 0.001"/>
      </geometry>
      <material
        name="">
        <color
          rgba="0.792156862745098 0.819607843137255 0.933333333333333 1" />
      </material>
    </visual>
    <collision>
      <origin
        xyz="0 0 0"
        rpy="0 0 0" />
      <geometry>
        <mesh
          filename="package://amr_description/meshes/delivery_box.stl" scale="0.001 0.001 0.001" />
      </geometry>
    </collision>
    <!--inertial>
      <origin
        xyz="0.03 0 0.03"
        rpy="0 0 0" />
      <mass
        value="1.030" />
      <inertia
        ixx="7.791e-4"
        ixy="-0.013e-9"
        ixz="-1.04741e-7"
        iyy="8.515e-4"
        iyz="2.7531e-8"
        izz="7.801e-4" />
    </inertial-->
  </link>

  <joint name="del_box_connector" type="continuous">
      <parent link="connector"/>
      <child link="delivery_box"/>
      <origin xyz="0 0 0.1" rpy="0 0 0"/>
      <axis xyz="0 1 0"/>
  </joint>

  


</robot>
